Workbook
Name StartingBalance: Summary!$L$8

Sheet Summary
B2: GET STARTED | I2: NOTE
B3: Set your starting balance in cell L8, then customize your categories and planned spending amounts in the 'Income' and 'Expenses' tables below. | I3: Only edit highlighted cells.
I4: Try not to alter cells that contain a formula.
B5: As you enter data in the 'Transactions' tab, this sheet will automatically update to show a summary of your spending for the month.
B8: Monthly Budget | J8: Starting balance: | L8: 0
D12: =IFERROR(__xludf.DUMMYFUNCTION("SPARKLINE(D17,{""charttype"",""column"";""ymin"", 0; ""ymax"",MAX(D17:E17);""firstcolor"",""#334960""})"),"") | E12: =IFERROR(__xludf.DUMMYFUNCTION("SPARKLINE(E17,{""charttype"",""column"";""ymin"", 0; ""ymax"",max(D17:E17);""firstcolor"",""#f46524""})"),"")
I13: =iferror(E17/D17-1, "")
I14: =if(I13 < 0, "Decrease in total savings", "Increase in total savings") -> Increase in total savings
I15: =iferror(E17-D17, 0) -> 87160
D16: START BALANCE | E16: END BALANCE | I16: =if(J15<0, "Spent this month", "Saved this month") -> Saved this month
D17: =if(isblank(L8),0,L8) -> 0 | E17: =D17+(I22-C22) -> 87160
B20: Expenses | H20: Income
B21: Planned | C21: =D26 -> 61199 | D21: =IFERROR(__xludf.DUMMYFUNCTION("SPARKLINE(C21,{""charttype"",""bar"";""max"",max(C21:C22);""color1"",""#AEB7C0""})"),"") | H21: Planned | I21: =J26 -> 182500 | J21: =IFERROR(__xludf.DUMMYFUNCTION("SPARKLINE(I21,{""charttype"",""bar"";""max"",max(I21:I22);""color1"",""#AEB7C0""})"),"")
B22: Actual | C22: =E26 -> 95108 | D22: =IFERROR(__xludf.DUMMYFUNCTION("SPARKLINE(C22,{""charttype"",""bar"";""max"",max(C21:C22);""color1"",""#334960""})"),"") | H22: Actual | I22: =K26 -> 182268 | J22: =IFERROR(__xludf.DUMMYFUNCTION("SPARKLINE(I22,{""charttype"",""bar"";""max"",max(I21:I22);""color1"",""#334960""})"),"")
B24: Expenses | H24: Income
D25: Planned | E25: Actual | F25: Diff. | J25: Planned | K25: Actual | L25: Diff.
B26: Totals | D26: =sum(D27:D44) -> 61199 | E26: =sum(E27:E44) -> 95108 | F26: =sum(F27:F44) -> -33909 | H26: Totals | J26: =sum(J27:J42) -> 182500 | K26: =sum(K27:K42) -> 182268 | L26: =sum(L27:L42) -> -232
E27: =if(isblank($B27), "", sumif(Transactions!$F:$F,$B27,Transactions!$D:$D)) | F27: =if(isblank($B27), "", D27-E27) | K27: =if(isblank($H27), "", sumif(Transactions!$K:$K,$H27,Transactions!$I:$I)) | L27: =if(isblank($H27), "", K27-J27)
B28: Groceries | D28: 8000 | E28: =if(isblank($B28), "", sumif(Transactions!$F:$F,$B28,Transactions!$D:$D)) -> 17428 | F28: =if(isblank($B28), "", D28-E28) -> -9428 | H28: Savings | J28: 0 | K28: =if(isblank($H28), "", sumif(Transactions!$K:$K,$H28,Transactions!$I:$I)) -> 0 | L28: =if(isblank($H28), "", K28-J28) -> 0
B29: Dineout | D29: 3000 | E29: =if(isblank($B29), "", sumif(Transactions!$F:$F,$B29,Transactions!$D:$D)) -> 3870 | F29: =if(isblank($B29), "", D29-E29) -> -870 | H29: Paycheck | J29: 182000 | K29: =if(isblank($H29), "", sumif(Transactions!$K:$K,$H29,Transactions!$I:$I)) -> 182000 | L29: =if(isblank($H29), "", K29-J29) -> 0
B30: Health/medical | D30: 10000 | E30: =if(isblank($B30), "", sumif(Transactions!$F:$F,$B30,Transactions!$D:$D)) -> 29508 | F30: =if(isblank($B30), "", D30-E30) -> -19508 | H30: Bonus | J30: 0 | K30: =if(isblank($H30), "", sumif(Transactions!$K:$K,$H30,Transactions!$I:$I)) -> 0 | L30: =if(isblank($H30), "", K30-J30) -> 0
B31: Home Rent | D31: 22000 | E31: =if(isblank($B31), "", sumif(Transactions!$F:$F,$B31,Transactions!$D:$D)) -> 22000 | F31: =if(isblank($B31), "", D31-E31) -> 0 | H31: Interest | J31: 0 | K31: =if(isblank($H31), "", sumif(Transactions!$K:$K,$H31,Transactions!$I:$I)) -> 0 | L31: =if(isblank($H31), "", K31-J31) -> 0
B32: Insurance | D32: 0 | E32: =if(isblank($B32), "", sumif(Transactions!$F:$F,$B32,Transactions!$D:$D)) -> 0 | F32: =if(isblank($B32), "", D32-E32) -> 0 | H32: Other | J32: 500 | K32: =if(isblank($H32), "", sumif(Transactions!$K:$K,$H32,Transactions!$I:$I)) -> 268 | L32: =if(isblank($H32), "", K32-J32) -> -232
B33: Petrol | D33: 2000 | E33: =if(isblank($B33), "", sumif(Transactions!$F:$F,$B33,Transactions!$D:$D)) -> 880 | F33: =if(isblank($B33), "", D33-E33) -> 1120 | H33: Custom category | J33: 0 | K33: =if(isblank($H33), "", sumif(Transactions!$K:$K,$H33,Transactions!$I:$I)) -> 0 | L33: =if(isblank($H33), "", K33-J33) -> 0
B34: Subscriptions | D34: 199 | E34: =if(isblank($B34), "", sumif(Transactions!$F:$F,$B34,Transactions!$D:$D)) -> 199 | F34: =if(isblank($B34), "", D34-E34) -> 0 | K34: =if(isblank($H34), "", sumif(Transactions!$K:$K,$H34,Transactions!$I:$I)) | L34: =if(isblank($H34), "", K34-J34)
B35: Travel/Transportation | D35: 5000 | E35: =if(isblank($B35), "", sumif(Transactions!$F:$F,$B35,Transactions!$D:$D)) -> 0 | F35: =if(isblank($B35), "", D35-E35) -> 5000 | K35: =if(isblank($H35), "", sumif(Transactions!$K:$K,$H35,Transactions!$I:$I)) | L35: =if(isblank($H35), "", K35-J35)
B36: Personal | D36: 3000 | E36: =if(isblank($B36), "", sumif(Transactions!$F:$F,$B36,Transactions!$D:$D)) -> 17282 | F36: =if(isblank($B36), "", D36-E36) -> -14282 | K36: =if(isblank($H36), "", sumif(Transactions!$K:$K,$H36,Transactions!$I:$I)) | L36: =if(isblank($H36), "", K36-J36)
B37: Utilities | D37: 2000 | E37: =if(isblank($B37), "", sumif(Transactions!$F:$F,$B37,Transactions!$D:$D)) -> 1449 | F37: =if(isblank($B37), "", D37-E37) -> 551 | K37: =if(isblank($H37), "", sumif(Transactions!$K:$K,$H37,Transactions!$I:$I)) | L37: =if(isblank($H37), "", K37-J37)
B38: Shopping | D38: 5000 | E38: =if(isblank($B38), "", sumif(Transactions!$F:$F,$B38,Transactions!$D:$D)) -> 1402 | F38: =if(isblank($B38), "", D38-E38) -> 3598 | K38: =if(isblank($H38), "", sumif(Transactions!$K:$K,$H38,Transactions!$I:$I)) | L38: =if(isblank($H38), "", K38-J38)
B39: Gifts/Donation | D39: 0 | E39: =if(isblank($B39), "", sumif(Transactions!$F:$F,$B39,Transactions!$D:$D)) -> 0 | F39: =if(isblank($B39), "", D39-E39) -> 0 | K39: =if(isblank($H39), "", sumif(Transactions!$K:$K,$H39,Transactions!$I:$I)) | L39: =if(isblank($H39), "", K39-J39)
B40: Other | D40: 1000 | E40: =if(isblank($B40), "", sumif(Transactions!$F:$F,$B40,Transactions!$D:$D)) -> 1090 | F40: =if(isblank($B40), "", D40-E40) -> -90 | K40: =if(isblank($H40), "", sumif(Transactions!$K:$K,$H40,Transactions!$I:$I)) | L40: =if(isblank($H40), "", K40-J40)
B41: Gym/Sports | D41: 0 | E41: =if(isblank($B41), "", sumif(Transactions!$F:$F,$B41,Transactions!$D:$D)) -> 0 | F41: =if(isblank($B41), "", D41-E41) -> 0
K42: =if(isblank($H42), "", sumif(Transactions!$K:$K,$H42,Transactions!$I:$I)) | L42: =if(isblank($H42), "", K42-J42)

Sheet Transactions
B1: Change or add categories by updating the Expenses and Income tables in the Summary sheet.
B2: Expenses | H2: Income
B4: Date | D4: Amount | E4: Description | F4: Category | H4: Date | I4: Amount | J4: Description | K4: Category
B6: 46266 | D6: 200 | E6: Chips + Laddu | F6: Dineout | H6: 46265 | I6: 182000 | J6: Salary | K6: Paycheck
B7: 46266 | D7: 145 | E7: Sweets | F7: Dineout | H7: 46263 | I7: 268 | J7: Amazon Credit card cash back | K7: Other
B8: 46266 | D8: 681 | E8: Babies Diapers | F8: Health/medical | H8: 46245 | I8: 0 | J8: Axis credit card cash back | K8: Other
B9: 46266 | D9: 789 | E9: Babies Diapers | F9: Health/medical
B10: 46266 | D10: 90 | E10: Kari kari Rice Crackers | F10: Dineout
B11: 46267 | D11: 357 | E11: Vegetables + milk | F11: Groceries
B12: 46267 | D12: 22000 | E12: Aug Rent | F12: Home Rent
B13: 46267 | D13: 483 | E13: Vegetables | F13: Groceries
B14: 46267 | D14: 160 | E14: Onions | F14: Groceries
B15: 46267 | D15: 375 | E15: Alergy medicine - cold | F15: Health/medical
B16: 46267 | D16: 20 | E16: Tea Udupi | F16: Dineout
B17: 46268 | D17: 34 | E17: Curd | F17: Groceries
B18: 46267 | D18: 4500 | E18: House help salary | F18: Personal
B19: 46269 | D19: 800 | E19: Anji doctors consultation | F19: Health/medical
B20: 46269 | D20: 1002 | E20: Anji medicine | F20: Health/medical
... B22: 46269 | D22: 692 | E22: My GS Appointment | F22: Health/medical
B23: 46269 | D23: =20+20 -> 40 | E23: Tea Udupi | F23: Dineout
B24: 46269 | D24: 40 | E24: Ice cream | F24: Dineout
B25: 46270 | D25: 138 | E25: Banana | F25: Groceries
B26: 46270 | D26: 260 | E26: Breakfast Udupi Gardenia | F26: Dineout
B27: 46270 | D27: 27 | E27: Milk | F27: Groceries
B28: 46270 | D28: 1000 | E28: Gas cylinder ￼ | F28: Utilities
B29: 46270 | D29: 190 | E29: Pani puri | F29: Dineout
B30: 46270 | D30: 2262 | E30: Smart bazar | F30: Groceries
B31: 46271 | D31: =20+20 -> 40 | E31: Tea | F31: Dineout
B32: 46271 | D32: 100 | E32: Hair cut | F32: Personal
B33: 46271 | D33: 350 | E33: iPhone 16 screen protector | F33: Personal
B34: 46271 | D34: 120 | E34: Chat | F34: Dineout
B35: 46272 | D35: 304 | E35: Fruits | F35: Groceries
B36: 46272 | D36: 20 | E36: Tea | F36: Dineout
B37: 46273 | D37: 20 | E37: Coffee | F37: Dineout
B38: 46273 | D38: 20 | E38: Tea | F38: Dineout
B39: 46274 | D39: 140 | E39: Breakfast Udupi | F39: Dineout
B40: 46274 | D40: 704 | E40: Curd maker | F40: Shopping
B41: 46274 | D41: 2480 | E41: Anvi blood test | F41: Health/medical
B42: 46274 | D42: 164 | E42: Vegetables | F42: Groceries
B43: 46274 | D43: 70 | E43: Pani puri | F43: Dineout
...

Sheet Visualization
